Workbook
Name _LOG1: [1]inst!#REF!
Name _LOG10: [1]inst!#REF!
Name _LOG11: [1]inst!#REF!
Name _LOG2: [1]inst!#REF!
Name _LOG3: [1]inst!#REF!
Name _LOG4: [1]inst!#REF!
Name _LOG5: [1]inst!#REF!
Name _LOG6: [1]inst!#REF!
Name _LOG7: [1]inst!#REF!
Name _LOG8: [1]inst!#REF!
Name _LOG9: [1]inst!#REF!
Name A: '[2]Gland Data'!$G$5
Name ACT: [1]inst!#REF!
Name AREA: [1]inst!#REF!
Name B: '[2]Gland Data'!$G$26
Name BQ: [1]inst!#REF!
Name contingency_1: #REF!
Name disc: [1]inst!#REF!
Name DWGN: [1]inst!#REF!
Name formrange1: #REF!
Name JETTY: [1]inst!#REF!
Name MCCB: '[2]Cable Data'!#REF!
Name MV: [1]inst!#REF!
Name P: #REF!
Name P: #REF!
Name P0: #REF!
Name P0: #REF!
Name PCT: [1]inst!#REF!
Name PLFA: [1]inst!#REF!
Name PLFS: [1]inst!#REF!
Name PLST: [1]inst!#REF!
Name Print_Area_MI: #REF!
Name Print_Area_MI: #REF!
Name QTY: [1]inst!#REF!
Name RES: [1]inst!#REF!
Name sht: #REF!
Name SS: [1]inst!#REF!
Name TITLE: [1]inst!#REF!

Sheet Cover-Page
A13: INSTRUMENT I/O LIST
H33: CLIENT: | J33: PT Marunda Tank Terminal | L33: CLIENT DOC NO. | M33: 24E11-J1-LI-1002
L34: JOB NO. | M34: 24E11
L35: PAGE NO. | M35: 1 OF 18
A36: 0 | B36: 23-06-2025 | C36: APPROVED FOR DESIGN | E36: WYJ | F36: LXL | G36: APM | H36: DESIGN ENGINEER: | L36: PROJECT TITLE | M36: PT Marunda Tank Terminal Storage Project
A37: A | B37: 23-01-2025 | C37: ISSUED FOR APPROVAL | E37: WYJ | F37: LXL | G37: APM | J37: Abraham International Process Engineering Corp Pte. Ltd
A38: REV | B38: DATE | C38: DESCRIPTION | E38: PREPARED BY | F38: CHECKED BY | G38: APPROVED BY | L38: LOCATION | M38: Tanah Abang, Jakarta Pusat, Indonesia

Sheet IO Summary
A1: Instrument I/O Summary
A2: S/N | B2: Area | C2: DI | D2: DO | E2: AI | F2: AO | G2: PI | H2: Remarks
A3: 1 | B3: TF-01 | C3: =COUNTIF(TF!$I$4:$I$179,C2) -> 112 | D3: =COUNTIF(TF!$I$4:$I$179,D2) -> 48 | E3: =COUNTIF(TF!$I$4:$I$179,E2) -> 16 | F3: =COUNTIF(TF!$I$4:$I$179,F2) -> 0 | G3: =COUNTIF(TF!$I$4:$I$179,G2) -> 0
A4: =A3+1 -> 2 | B4: PUMP STATION | C4: =COUNTIF(PUMPS!$I$4:$I$58,C2) -> 20 | D4: =COUNTIF(PUMPS!$I$4:$I$58,D2) -> 14 | E4: =COUNTIF(PUMPS!$I$4:$I$58,E2) -> 15 | F4: =COUNTIF(PUMPS!$I$4:$I$58,F2) -> 6 | G4: =COUNTIF(PUMPS!$I$4:$I$58,G2) -> 0
A5: =A4+1 -> 3 | B5: JETTY | C5: =COUNTIF(JETTY!$I$4:$I$10,C2) -> 4 | D5: =COUNTIF(JETTY!$I$4:$I$10,D2) -> 2 | E5: =COUNTIF(JETTY!$I$4:$I$10,E2) -> 1 | F5: =COUNTIF(JETTY!$I$4:$I$10,F2) -> 0 | G5: =COUNTIF(JETTY!$I$4:$I$10,G2) -> 0
A6: =A5+1 -> 4 | B6: TLB | C6: =COUNTIF(TLB!$I$4:$I$108,C2) -> 48 | D6: =COUNTIF(TLB!$I$4:$I$108,D2) -> 16 | E6: =COUNTIF(TLB!$I$4:$I$108,E2) -> 33 | F6: =COUNTIF(TLB!$I$4:$I$108,F2) -> 8 | G6: =COUNTIF(TLB!$I$4:$I$108,G2) -> 0
A7: =A6+1 -> 5 | B7: HOT WATER SYS. | C7: =COUNTIF('HOT WATER'!$I$4:$I$29,C2) -> 22 | D7: =COUNTIF('HOT WATER'!$I$4:$I$29,D2) -> 0 | E7: =COUNTIF('HOT WATER'!$I$4:$I$29,E2) -> 4 | F7: =COUNTIF('HOT WATER'!$I$4:$I$29,F2) -> 0 | G7: =COUNTIF('HOT WATER'!$I$4:$I$29,G2) -> 0
A8: =A7+1 -> 6 | B8: POTABLE WATER SYS. | C8: =COUNTIF('POTABLE WATER'!$I$4:$I$15,C2) -> 9 | D8: =COUNTIF('POTABLE WATER'!$I$4:$I$15,D2) -> 0 | E8: =COUNTIF('POTABLE WATER'!$I$4:$I$15,E2) -> 3 | F8: =COUNTIF('POTABLE WATER'!$I$4:$I$15,F2) -> 0 | G8: =COUNTIF('POTABLE WATER'!$I$4:$I$15,G2) -> 0
A9: =A8+1 -> 7 | B9: PLANT AIR SYS. | C9: =COUNTIF('PLANT AIR'!$I$4:$I$11,C2) -> 6 | D9: =COUNTIF('PLANT AIR'!$I$4:$I$11,D2) -> 0 | E9: =COUNTIF('PLANT AIR'!$I$4:$I$11,E2) -> 2 | F9: =COUNTIF('PLANT AIR'!$I$4:$I$11,F2) -> 0 | G9: =COUNTIF('PLANT AIR'!$I$4:$I$11,G2) -> 0
A10: =A9+1 -> 8 | B10: 10% Feed Margin | C10: =ROUNDUP(SUM(C$3:C$9)*1.1,0) -> 244 | D10: =ROUNDUP(SUM(D$3:D$9)*1.1,0) -> 88 | E10: =ROUNDUP(SUM(E$3:E$9)*1.1,0) -> 82 | F10: =ROUNDUP(SUM(F$3:F$9)*1.1,0) -> 16 | G10: =SUM(G$3:G$9)*1.1 -> 0
A11: =A10+1 -> 9 | B11: Including 20% Spare | C11: =ROUNDUP(C10*1.2,0) -> 293 | D11: =ROUNDUP(D10*1.2,0) -> 106 | E11: =ROUNDUP(E10*1.2,0) -> 99 | F11: =ROUNDUP(F10*1.2,0) -> 20 | G11: =ROUNDUP(G10*1.2,0) -> 0
A12: This is preliminary IO list and will be finalized during detail design.

Sheet TF
A1: S/N | B1: Revision No. | C1: DCS Tag Number | D1: Instrument Tag No. | E1: Signal Description | F1: Equipment | G1: P & ID Dwg No. | H1: P&ID Revision No. | I1: IO Type | J1: Signal Type | K1: Power | L1: Zero Stauts | M1: One Stauts | N1: Alarm Setting | R1: Range | T1: Unit | U1: RIO Panel No. | V1: Slot Number | W1: Channel Number | X1: Remarks
N2: LL | O2: L | P2: H | Q2: HH | R2: 0 | S2: 1 | Y2: used | Z2: spare
A3: INSTRUMENT I/O FOR TANK FARM 01
A4: =ROW()-3 -> 1 | B4: A | C4: 01LSHH0101 | D4: 01-LS-0101 | E4: T-101 Level Switch | F4: T-101 | G4: 24E11-P1-PI-1002 | H4: A | I4: DI | J4: Dry Contact | K4: -
A5: =ROW()-3 -> 2 | B5: A | C5: 01LSHH0201 | D5: 01-LS-0201 | E5: T-102 Level Switch | F5: T-102 | G5: 24E11-P1-PI-1002 | H5: A | I5: DI | J5: Dry Contact | K5: -
A6: =ROW()-3 -> 3 | B6: A | C6: 01LSHH0301 | D6: 01-LS-0301 | E6: T-103 Level Switch | F6: T-103 | G6: 24E11-P1-PI-1002 | H6: A | I6: DI | J6: Dry Contact | K6: -
A7: =ROW()-3 -> 4 | B7: A | C7: 01LSHH0401 | D7: 01-LS-0401 | E7: T-104 Level Switch | F7: T-104 | G7: 24E11-P1-PI-1002 | H7: A | I7: DI | J7: Dry Contact | K7: -
A8: =ROW()-3 -> 5 | B8: A | C8: 01LSHH0501 | D8: 01-LS-0501 | E8: T-105 Level Switch | F8: T-105 | G8: 24E11-P1-PI-1001 | H8: A | I8: DI | J8: Dry Contact | K8: -
A9: =ROW()-3 -> 6 | B9: A | C9: 01LSHH0601 | D9: 01-LS-0601 | E9: T-106 Level Switch | F9: T-106 | G9: 24E11-P1-PI-1001 | H9: A | I9: DI | J9: Dry Contact | K9: -
A10: =ROW()-3 -> 7 | B10: A | C10: 01LSHH0701 | D10: 01-LS-0701 | E10: T-107 Level Switch | F10: T-107 | G10: 24E11-P1-PI-1001 | H10: A | I10: DI | J10: Dry Contact | K10: -
A11: =ROW()-3 -> 8 | B11: A | C11: 01LSHH0801 | D11: 01-LS-0801 | E11: T-108 Level Switch | F11: T-108 | G11: 24E11-P1-PI-1001 | H11: A | I11: DI | J11: Dry Contact | K11: -
A12: =ROW()-3 -> 9 | B12: A | C12: 01LALL0101 | D12: 01-LS-0101 | E12: T-101 Radar Gauge Switch Output | F12: T-101 | G12: 24E11-P1-PI-1002 | H12: A | I12: DI | J12: Dry Contact | K12: -
A13: =ROW()-3 -> 10 | B13: A | C13: 01LALL0201 | D13: 01-LS-0201 | E13: T-102 Radar Gauge Switch Output | F13: T-102 | G13: 24E11-P1-PI-1002 | H13: A | I13: DI | J13: Dry Contact | K13: -
A14: =ROW()-3 -> 11 | B14: A | C14: 01LALL0301 | D14: 01-LS-0301 | E14: T-103 Radar Gauge Switch Output | F14: T-103 | G14: 24E11-P1-PI-1002 | H14: A | I14: DI | J14: Dry Contact | K14: -
A15: =ROW()-3 -> 12 | B15: A | C15: 01LALL0401 | D15: 01-LS-0401 | E15: T-104 Radar Gauge Switch Output | F15: T-104 | G15: 24E11-P1-PI-1002 | H15: A | I15: DI | J15: Dry Contact | K15: -
... A19: =ROW()-3 -> 16 | B19: A | C19: 01LALL0801 | D19: 01-LS-0801 | E19: T-108 Radar Gauge Switch Output | F19: T-108 | G19: 24E11-P1-PI-1001 | H19: A | I19: DI | J19: Dry Contact | K19: -
A20: =ROW()-3 -> 17 | B20: A | C20: 01TI0102 | D20: 01-TT-0102 | E20: T-101 Temperature | F20: T-101 | G20: 24E11-P1-PI-1002 | H20: A | I20: AI | J20: 4~20mA | K20: Loop Powered | L20: - | M20: - | R20: 0 | S20: 100 | T20: ℃
A21: =ROW()-3 -> 18 | B21: A | C21: 01TI0202 | D21: 01-TT-0202 | E21: T-102 Temperature | F21: T-102 | G21: 24E11-P1-PI-1002 | H21: A | I21: AI | J21: 4~20mA | K21: Loop Powered | L21: - | M21: - | R21: 0 | S21: 100 | T21: ℃
A22: =ROW()-3 -> 19 | B22: A | C22: 01TI0302 | D22: 01-TT-0302 | E22: T-103 Temperature | F22: T-103 | G22: 24E11-P1-PI-1002 | H22: A | I22: AI | J22: 4~20mA | K22: Loop Powered | L22: - | M22: - | R22: 0 | S22: 100 | T22: ℃
A23: =ROW()-3 -> 20 | B23: A | C23: 01TI0402 | D23: 01-TT-0402 | E23: T-104 Temperature | F23: T-104 | G23: 24E11-P1-PI-1002 | H23: A | I23: AI | J23: 4~20mA | K23: Loop Powered | L23: - | M23: - | R23: 0 | S23: 100 | T23: ℃
A24: =ROW()-3 -> 21 | B24: A | C24: 01TI0502 | D24: 01-TT-0502 | E24: T-105 Temperature | F24: T-105 | G24: 24E11-P1-PI-1001 | H24: A | I24: AI | J24: 4~20mA | K24: Loop Powered | L24: - | M24: - | R24: 0 | S24: 100 | T24: ℃
A25: =ROW()-3 -> 22 | B25: A | C25: 01TI0602 | D25: 01-TT-0602 | E25: T-106 Temperature | F25: T-106 | G25: 24E11-P1-PI-1001 | H25: A | I25: AI | J25: 4~20mA | K25: Loop Powered | L25: - | M25: - | R25: 0 | S25: 100 | T25: ℃
A26: =ROW()-3 -> 23 | B26: A | C26: 01TI0702 | D26: 01-TT-0702 | E26: T-107 Temperature | F26: T-107 | G26: 24E11-P1-PI-1001 | H26: A | I26: AI | J26: 4~20mA | K26: Loop Powered | L26: - | M26: - | R26: 0 | S26: 100 | T26: ℃
A27: =ROW()-3 -> 24 | B27: A | C27: 01TI0802 | D27: 01-TT-0802 | E27: T-108 Temperature | F27: T-108 | G27: 24E11-P1-PI-1001 | H27: A | I27: AI | J27: 4~20mA | K27: Loop Powered | L27: - | M27: - | R27: 0 | S27: 100 | T27: ℃
A28: =ROW()-3 -> 25 | B28: A | C28: 01ZLL0101 | D28: 01-ZSL-0101 | E28: 01-MOV-0101 Fully Closed | F28: 01-MOV-0101 | G28: 24E11-P1-PI-1002 | H28: A | I28: DI | J28: Dry Contact | K28: - | L28: - | M28: Closed
A29: =ROW()-3 -> 26 | B29: A | C29: 01ZLH0101 | D29: 01-ZSH-0101 | E29: 01-MOV-0101 Fully Open | F29: 01-MOV-0101 | G29: 24E11-P1-PI-1002 | H29: A | I29: DI | J29: Dry Contact | K29: - | L29: - | M29: Open
A30: =ROW()-3 -> 27 | B30: A | C30: 01XS0101 | D30: 01-HS-0101 | E30: Local/Remote/Off Switch | F30: 01-MOV-0101 | G30: 24E11-P1-PI-1002 | H30: A | I30: DI | J30: Dry Contact | K30: - | L30: Remote | M30: Local/Off
A31: =ROW()-3 -> 28 | B31: 0 | C31: 01XA0101 | D31: 01-XA-0101 | E31: Fault | F31: 01-MOV-0101 | G31: 24E11-P1-PI-1002 | H31: A | I31: DI | J31: Dry Contact | K31: - | L31: - | M31: Alarm
A32: =ROW()-3 -> 29 | B32: A | C32: 01HSC0101 | D32: 01-MOV-0101 | E32: 01-MOV-0101 Open Command | F32: 01-MOV-0101 | G32: 24E11-P1-PI-1002 | H32: A | I32: DO | J32: Dry Contact | K32: - | L32: - | M32: Open
A33: =ROW()-3 -> 30 | B33: A | C33: 01HSO0101 | D33: 01-MOV-0101 | E33: 01-MOV-0101 Close Command | F33: 01-MOV-0101 | G33: 24E11-P1-PI-1002 | H33: A | I33: DO | J33: Dry Contact | K33: - | L33: - | M33: Close
A34: =ROW()-3 -> 31 | B34: A | C34: 01ZLL0102 | D34: 01-ZSL-0102 | E34: 01-MOV-0102 Fully Closed | F34: 01-MOV-0102 | G34: 24E11-P1-PI-1002 | H34: A | I34: DI | J34: Dry Contact | K34: - | L34: - | M34: Closed
A35: =ROW()-3 -> 32 | B35: A | C35: 01ZLH0102 | D35: 01-ZSH-0102 | E35: 01-MOV-0102 Fully Open | F35: 01-MOV-0102 | G35: 24E11-P1-PI-1002 | H35: A | I35: DI | J35: Dry Contact | K35: - | L35: - | M35: Open
A36: =ROW()-3 -> 33 | B36: A | C36: 01XS0102 | D36: 01-HS-0102 | E36: Local/Remote/Off Switch | F36: 01-MOV-0102 | G36: 24E11-P1-PI-1002 | H36: A | I36: DI | J36: Dry Contact | K36: - | L36: Remote | M36: Local/Off
A37: =ROW()-3 -> 34 | B37: 0 | C37: 01XA0102 | D37: 01-XA-0102 | E37: Fault | F37: 01-MOV-0102 | G37: 24E11-P1-PI-1002 | H37: A | I37: DI | J37: Dry Contact | K37: - | L37: - | M37: Alarm
A38: =ROW()-3 -> 35 | B38: A | C38: 01HSC0102 | D38: 01-MOV-0102 | E38: 01-MOV-0102 Open Command | F38: 01-MOV-0102 | G38: 24E11-P1-PI-1002 | H38: A | I38: DO | J38: Dry Contact | K38: - | L38: - | M38: Open
A39: =ROW()-3 -> 36 | B39: A | C39: 01HSO0102 | D39: 01-MOV-0102 | E39: 01-MOV-0102 Close Command | F39: 01-MOV-0102 | G39: 24E11-P1-PI-1002 | H39: A | I39: DO | J39: Dry Contact | K39: - | L39: - | M39: Close
A40: =ROW()-3 -> 37 | B40: A | C40: 01ZI0102 | D40: 01-ZT-0102 | E40: 01-MOV-0102 Opening Position Feedback | F40: 01-MOV-0102 | G40: 24E11-P1-PI-1002 | H40: A | I40: AI | J40: 4~20mA | K40: - | L40: - | M40: - | R40: 0 | S40: 100 | T40: %
A41: =ROW()-3 -> 38 | B41: A | C41: 01ZLL0103 | D41: 01-ZSL-0103 | E41: 01-MOV-0103 Fully Closed | F41: 01-MOV-0103 | G41: 24E11-P1-PI-1002 | H41: A | I41: DI | J41: Dry Contact | K41: - | L41: - | M41: Closed
A42: =ROW()-3 -> 39 | B42: A | C42: 01ZLH0103 | D42: 01-ZSH-0103 | E42: 01-MOV-0103 Fully Open | F42: 01-MOV-0103 | G42: 24E11-P1-PI-1002 | H42: A | I42: DI | J42: Dry Contact | K42: - | L42: - | M42: Open
A43: =ROW()-3 -> 40 | B43: A | C43: 01XS0103 | D43: 01-HS-0103 | E43: Local/Remote/Off Switch | F43: 01-MOV-0103 | G43: 24E11-P1-PI-1002 | H43: A | I43: DI | J43: Dry Contact | K43: - | L43: Remote | M43: Local/Off
...

Sheet PUMPS
A1: S/N | B1: Revision No. | C1: DCS Tag Number | D1: Instrument Tag No. | E1: Signal Description | F1: Equipment | G1: P & ID Dwg No. | H1: P&ID Revision No. | I1: IO Type | J1: Signal Type | K1: Power | L1: Zero Stauts | M1: One Stauts | N1: Alarm Setting | R1: Range | T1: Unit | U1: RIO Panel No. | V1: Slot Number | W1: Channel Number | X1: Remarks
N2: LL | O2: L | P2: H | Q2: HH | R2: 0 | S2: 1 | Y2: used | Z2: spare
A3: INSTRUMENT I/O FOR PUMP STATION 01
A4: =ROW()-3 -> 1 | B4: A | C4: 01TI0001 | D4: 01-TT-0001 | E4: P-101 Temperature | F4: P-101 | G4: 24E11-P1-PI-1004 | H4: A | I4: AI | J4: 4~20mA | K4: Loop Powered | L4: - | M4: -
A5: =ROW()-3 -> 2 | B5: A | C5: 01TI0002 | D5: 01-TT-0002 | E5: P-102 Temperature | F5: P-102 | G5: 24E11-P1-PI-1004 | H5: A | I5: AI | J5: 4~20mA | K5: Loop Powered | L5: - | M5: -
A6: =ROW()-3 -> 3 | B6: A | C6: 01TI0003 | D6: 01-TT-0003 | E6: P-103 Temperature | F6: P-103 | G6: 24E11-P1-PI-1004 | H6: A | I6: AI | J6: 4~20mA | K6: Loop Powered | L6: - | M6: -
A7: =ROW()-3 -> 4 | B7: A | C7: 01TI0004 | D7: 01-TT-0004 | E7: P-104 Temperature | F7: P-104 | G7: 24E11-P1-PI-1004 | H7: A | I7: AI | J7: 4~20mA | K7: Loop Powered | L7: - | M7: -
A8: =ROW()-3 -> 5 | B8: A | C8: 01TI0005 | D8: 01-TT-0005 | E8: P-105 Temperature | F8: P-105 | G8: 24E11-P1-PI-1004 | H8: A | I8: AI | J8: 4~20mA | K8: Loop Powered | L8: - | M8: -
A9: =ROW()-3 -> 6 | B9: A | C9: 01TI0006 | D9: 01-TT-0006 | E9: P-106 Temperature | F9: P-106 | G9: 24E11-P1-PI-1004 | H9: A | I9: AI | J9: 4~20mA | K9: Loop Powered | L9: - | M9: -
A10: =ROW()-3 -> 7 | B10: A | C10: 01TI0007 | D10: 01-TT-0007 | E10: P-107 Temperature | F10: P-107 | G10: 24E11-P1-PI-1004 | H10: A | I10: AI | J10: 4~20mA | K10: Loop Powered | L10: - | M10: -
A11: =ROW()-3 -> 8 | B11: A | C11: 04TI0001 | D11: 04-TT-0001 | E11: P-401 Temperature | F11: P-401 | G11: 24E11-P1-PI-1005 | H11: A | I11: AI | J11: 4~20mA | K11: Loop Powered | L11: - | M11: -
A12: =ROW()-3 -> 9 | B12: A | C12: 01LSL0001 | D12: 01-LSL-0001 | E12: P-101 Suction Low Level Protection | F12: P-101 | G12: 24E11-P1-PI-1004 | H12: A | I12: DI | J12: Dry Contact | K12: 24VDC | L12: - | M12: L Level
A13: =ROW()-3 -> 10 | B13: A | C13: 01LSL0002 | D13: 01-LSL-0002 | E13: P-102 Suction Low Level Protection | F13: P-102 | G13: 24E11-P1-PI-1004 | H13: A | I13: DI | J13: Dry Contact | K13: 24VDC | L13: - | M13: L Level
A14: =ROW()-3 -> 11 | B14: A | C14: 01LSL0003 | D14: 01-LSL-0003 | E14: P-103 Suction Low Level Protection | F14: P-103 | G14: 24E11-P1-PI-1004 | H14: A | I14: DI | J14: Dry Contact | K14: 24VDC | L14: - | M14: L Level
A15: =ROW()-3 -> 12 | B15: A | C15: 01LSL0004 | D15: 01-LSL-0004 | E15: P-104 Suction Low Level Protection | F15: P-104 | G15: 24E11-P1-PI-1004 | H15: A | I15: DI | J15: Dry Contact | K15: 24VDC | L15: - | M15: L Level
... A25: =ROW()-3 -> 22 | B25: A | C25: 01HS0001A | D25: 01-HS-0001A | E25: Remote/Off/Local Switch | F25: P-101 | G25: 24E11-P1-PI-1004 | H25: A | I25: DI | J25: Dry Contact | K25: - | L25: Remote | M25: Local/Off
A26: =ROW()-3 -> 23 | B26: 0 | C26: 01HS0001BA | D26: 01-HS-0001B | E26: Start Switch | F26: P-101 | G26: 24E11-P1-PI-1004 | H26: A | I26: DO | J26: Dry Contact | K26: - | L26: - | M26: Start
A27: =ROW()-3 -> 24 | B27: 0 | C27: 01HS0001BB | D27: 01-HS-0001B | E27: Stop Switch | F27: P-101 | G27: 24E11-P1-PI-1004 | H27: A | I27: DO | J27: Dry Contact | K27: - | L27: - | M27: Stop
A28: =ROW()-3 -> 25 | B28: A | C28: 01HS0001C | D28: 01-HS-0001C | E28: Running/Trip | F28: P-101 | G28: 24E11-P1-PI-1004 | H28: A | I28: DI | J28: Dry Contact | K28: - | L28: Trip | M28: Running
A29: =ROW()-3 -> 26 | B29: A | C29: 01SC0001 | D29: 01-SC-0001 | E29: VSD Speed Control | F29: P-101 | G29: 24E11-P1-PI-1004 | H29: A | I29: AO | J29: 4~20mA | L29: - | M29: -
A30: =ROW()-3 -> 27 | B30: A | C30: 01HS0002A | D30: 01-HS-0002A | E30: Remote/Off/Local Switch | F30: P-102 | G30: 24E11-P1-PI-1004 | H30: A | I30: DI | J30: Dry Contact | K30: - | L30: Remote | M30: Local/Off
A31: =ROW()-3 -> 28 | B31: 0 | C31: 01HS0002BA | D31: 01-HS-0002B | E31: Start Switch | F31: P-102 | G31: 24E11-P1-PI-1004 | H31: A | I31: DO | J31: Dry Contact | K31: - | L31: - | M31: Start
A32: =ROW()-3 -> 29 | B32: 0 | C32: 01HS0002BB | D32: 01-HS-0002B | E32: Stop Switch | F32: P-102 | G32: 24E11-P1-PI-1004 | H32: A | I32: DO | J32: Dry Contact | K32: - | L32: - | M32: Stop
A33: =ROW()-3 -> 30 | B33: A | C33: 01HS0002C | D33: 01-HS-0002C | E33: Running/Trip | F33: P-102 | G33: 24E11-P1-PI-1004 | H33: A | I33: DI | J33: Dry Contact | K33: - | L33: Trip | M33: Running
A34: =ROW()-3 -> 31 | B34: A | C34: 01SC0002 | D34: 01-SC-0002 | E34: VSD Speed Control | F34: P-102 | G34: 24E11-P1-PI-1004 | H34: A | I34: AO | J34: 4~20mA | L34: - | M34: -
A35: =ROW()-3 -> 32 | B35: A | C35: 01HS0003A | D35: 01-HS-0003A | E35: Remote/Off/Local Switch | F35: P-103 | G35: 24E11-P1-PI-1004 | H35: A | I35: DI | J35: Dry Contact | K35: - | L35: Remote | M35: Local/Off
A36: =ROW()-3 -> 33 | B36: 0 | C36: 01HS0003BA | D36: 01-HS-0003B | E36: Start Switch | F36: P-103 | G36: 24E11-P1-PI-1004 | H36: A | I36: DO | J36: Dry Contact | K36: - | L36: - | M36: Start
A37: =ROW()-3 -> 34 | B37: 0 | C37: 01HS0003BB | D37: 01-HS-0003B | E37: Stop Switch | F37: P-103 | G37: 24E11-P1-PI-1004 | H37: A | I37: DO | J37: Dry Contact | K37: - | L37: - | M37: Stop
A38: =ROW()-3 -> 35 | B38: A | C38: 01HS0003C | D38: 01-HS-0003C | E38: Running/Trip | F38: P-103 | G38: 24E11-P1-PI-1004 | H38: A | I38: DI | J38: Dry Contact | K38: - | L38: Trip | M38: Running
A39: =ROW()-3 -> 36 | B39: A | C39: 01SC0003 | D39: 01-SC-0003 | E39: VSD Speed Control | F39: P-103 | G39: 24E11-P1-PI-1004 | H39: A | I39: AO | J39: 4~20mA | L39: - | M39: -
A40: =ROW()-3 -> 37 | B40: A | C40: 01HS0004A | D40: 01-HS-0004A | E40: Remote/Off/Local Switch | F40: P-104 | G40: 24E11-P1-PI-1004 | H40: A | I40: DI | J40: Dry Contact | K40: - | L40: Remote | M40: Local/Off
A41: =ROW()-3 -> 38 | B41: 0 | C41: 01HS0004BA | D41: 01-HS-0004B | E41: Start Switch | F41: P-104 | G41: 24E11-P1-PI-1004 | H41: A | I41: DO | J41: Dry Contact | K41: - | L41: - | M41: Start
A42: =ROW()-3 -> 39 | B42: 0 | C42: 01HS0004BB | D42: 01-HS-0004B | E42: Stop Switch | F42: P-104 | G42: 24E11-P1-PI-1004 | H42: A | I42: DO | J42: Dry Contact | K42: - | L42: - | M42: Stop
A43: =ROW()-3 -> 40 | B43: A | C43: 01HS0004C | D43: 01-HS-0004C | E43: Running/Trip | F43: P-104 | G43: 24E11-P1-PI-1004 | H43: A | I43: DI | J43: Dry Contact | K43: - | L43: Trip | M43: Running
A44: =ROW()-3 -> 41 | B44: A | C44: 01SC0004 | D44: 01-SC-0004 | E44: VSD Speed Control | F44: P-104 | G44: 24E11-P1-PI-1004 | H44: A | I44: AO | J44: 4~20mA | L44: - | M44: -
A45: =ROW()-3 -> 42 | B45: A | C45: 01HS0005A | D45: 01-HS-0005A | E45: Remote/Off/Local Switch | F45: P-105 | G45: 24E11-P1-PI-1004 | H45: A | I45: DI | J45: Dry Contact | K45: - | L45: Remote | M45: Local/Off
A46: =ROW()-3 -> 43 | B46: 0 | C46: 01HS0005BA | D46: 01-HS-0005B | E46: Start Switch | F46: P-105 | G46: 24E11-P1-PI-1004 | H46: A | I46: DO | J46: Dry Contact | K46: - | L46: - | M46: Start
A47: =ROW()-3 -> 44 | B47: 0 | C47: 01HS0005BB | D47: 01-HS-0005B | E47: Stop Switch | F47: P-105 | G47: 24E11-P1-PI-1004 | H47: A | I47: DO | J47: Dry Contact | K47: - | L47: - | M47: Stop
A48: =ROW()-3 -> 45 | B48: A | C48: 01HS0005C | D48: 01-HS-0005C | E48: Running/Trip | F48: P-105 | G48: 24E11-P1-PI-1004 | H48: A | I48: DI | J48: Dry Contact | K48: - | L48: Trip | M48: Running
A49: =ROW()-3 -> 46 | B49: A | C49: 01SC0005 | D49: 01-SC-0005 | E49: VSD Speed Control | F49: P-105 | G49: 24E11-P1-PI-1004 | H49: A | I49: AO | J49: 4~20mA | L49: - | M49: -
...

Sheet JETTY
A1: S/N | B1: Revision No. | C1: DCS Tag Number | D1: Instrument Tag No. | E1: Signal Description | F1: Equipment | G1: P & ID Dwg No. | H1: P&ID Revision No. | I1: IO Type | J1: Signal Type | K1: Power | L1: Zero Stauts | M1: One Stauts | N1: Alarm Setting | R1: Range | T1: Unit | U1: RIO Panel No. | V1: Slot Number | W1: Channel Number | X1: Remarks
N2: LL | O2: L | P2: H | Q2: HH | R2: 0 | S2: 1 | Y2: used | Z2: spare
A3: INSTRUMENT I/O FOR JETTY AREA
A4: =ROW()-3 -> 1 | B4: A | C4: 03PI0001 | D4: 03-PT-0001 | E4: PLR-301 Discharge Line Pressure | F4: PL-0301-8''-150A1 | G4: 24E11-P1-PI-1001 | H4: A | I4: AI | J4: 4~20mA | K4: Loop Powered | L4: - | M4: - | R4: 0 | S4: 16 | T4: Barg | X4: HOLD
A5: =ROW()-3 -> 2 | B5: A | C5: 03ZLL0001 | D5: 03-ZSL-0001 | E5: 03-MOV-0001 Fully Closed | F5: 03-MOV-0001 | G5: 24E11-P1-PI-1001 | H5: A | I5: DI | J5: Dry Contact | K5: - | L5: - | M5: Closed
A6: =ROW()-3 -> 3 | B6: A | C6: 03ZLH0001 | D6: 03-ZSH-0001 | E6: 03-MOV-0001 Fully Open | F6: 03-MOV-0001 | G6: 24E11-P1-PI-1001 | H6: A | I6: DI | J6: Dry Contact | K6: - | L6: - | M6: Open
A7: =ROW()-3 -> 4 | B7: A | C7: 03XS0001 | D7: 03-HS-0001 | E7: Local/Remote/Off Switch | F7: 03-MOV-0001 | G7: 24E11-P1-PI-1001 | H7: A | I7: DI | J7: Dry Contact | K7: - | L7: Remote | M7: Local/Off
A8: =ROW()-3 -> 5 | B8: 0 | C8: 03XA0001 | D8: 03-XA-0001 | E8: Fault | F8: 03-MOV-0001 | G8: 24E11-P1-PI-1001 | H8: A | I8: DI | J8: Dry Contact | K8: - | L8: - | M8: Alarm
A9: =ROW()-3 -> 6 | B9: A | C9: 03HSC0001 | D9: 03-MOV-0001 | E9: 03-MOV-0001 Close Command | F9: 03-MOV-0001 | G9: 24E11-P1-PI-1001 | H9: A | I9: DO | J9: Dry Contact | K9: - | L9: - | M9: Open
A10: =ROW()-3 -> 7 | B10: A | C10: 03HSO0001 | D10: 03-MOV-0001 | E10: 03-MOV-0001 Open Command | F10: 03-MOV-0001 | G10: 24E11-P1-PI-1001 | H10: A | I10: DO | J10: Dry Contact | K10: - | L10: - | M10: Close

Sheet TLB
A1: S/N | B1: Revision No. | C1: DCS Tag Number | D1: Instrument Tag No. | E1: Signal Description | F1: Equipment | G1: P & ID Dwg No. | H1: P&ID Revision No. | I1: IO Type | J1: Signal Type | K1: Power | L1: Zero Stauts | M1: One Stauts | N1: Alarm Setting | R1: Range | T1: Unit | U1: RIO Panel No. | V1: Slot Number | W1: Channel Number | X1: Remarks
N2: LL | O2: L | P2: H | Q2: HH | R2: 0 | S2: 1 | Y2: used | Z2: spare
A3: INSTRUMENT I/O FOR TRUCK LOADING AREA
A4: =ROW()-3 -> 1 | B4: A | C4: 04FI0101 | D4: 04-FT-0101 | E4: PLR-402 To Tuck Loading Bay 1 Line Flow | F4: PL-0408-4"-150A1 | G4: 24E11-P1-PI-1005 | H4: A | I4: AI | J4: 4~20mA | K4: Loop Powered | L4: - | M4: - | X4: HOLD
A5: =ROW()-3 -> 2 | B5: A | C5: 04FI0201 | D5: 04-FT-0201 | E5: PLR-402 To Tuck Loading Bay 2 Line Flow | F5: PL-0409-4"-150A1 | G5: 24E11-P1-PI-1005 | H5: A | I5: AI | J5: 4~20mA | K5: Loop Powered | L5: - | M5: - | X5: HOLD
A6: =ROW()-3 -> 3 | B6: A | C6: 04FI0301 | D6: 04-FT-0301 | E6: PLR-403 To Tuck Loading Bay 3 Line Flow | F6: PL-0412-4"-150A1 | G6: 24E11-P1-PI-1005 | H6: A | I6: AI | J6: 4~20mA | K6: Loop Powered | L6: - | M6: - | X6: HOLD
A7: =ROW()-3 -> 4 | B7: A | C7: 04FI0401 | D7: 04-FT-0401 | E7: PLR-403 To Tuck Loading Bay 4 Line Flow | F7: PL-0413-4"-150A1 | G7: 24E11-P1-PI-1005 | H7: A | I7: AI | J7: 4~20mA | K7: Loop Powered | L7: - | M7: - | X7: HOLD
A8: =ROW()-3 -> 5 | B8: A | C8: 04FI0501 | D8: 04-FT-0501 | E8: PLR-404 To Truck Loading Bay 5 Line Flow | F8: PL-0416-4"-150A1 | G8: 24E11-P1-PI-1006 | H8: A | I8: AI | J8: 4~20mA | K8: Loop Powered | L8: - | M8: - | X8: HOLD
A9: =ROW()-3 -> 6 | B9: A | C9: 04FI0601 | D9: 04-FT-0601 | E9: PLR-404 To Truck Loading Bay 6 Line Flow | F9: PL-0417-4"-150A1 | G9: 24E11-P1-PI-1006 | H9: A | I9: AI | J9: 4~20mA | K9: Loop Powered | L9: - | M9: - | X9: HOLD
A10: =ROW()-3 -> 7 | B10: A | C10: 04FI0701 | D10: 04-FT-0701 | E10: PLR-405 To Truck Loading Bay 7 Line Flow | F10: PL-0420-4"-150A1 | G10: 24E11-P1-PI-1006 | H10: A | I10: AI | J10: 4~20mA | K10: Loop Powered | L10: - | M10: - | X10: HOLD
A11: =ROW()-3 -> 8 | B11: A | C11: 04FI0801 | D11: 04-FT-0801 | E11: PLR-405 To Truck Loading Bay 8 Line Flow | F11: PL-0421-4"-150A1 | G11: 24E11-P1-PI-1006 | H11: A | I11: AI | J11: 4~20mA | K11: Loop Powered | L11: - | M11: - | X11: HOLD
A12: =ROW()-3 -> 9 | B12: A | C12: 04ZC0101 | D12: 04-ZC-0101 | E12: 04-FCV-0101 Opening Control | F12: PL-0408-4"-150A1 | G12: 24E11-P1-PI-1005 | H12: A | I12: AO | J12: 4~20mA | K12: Loop Powered | L12: - | M12: - | R12: 0 | S12: 100 | T12: % | X12: HOLD
A13: =ROW()-3 -> 10 | B13: A | C13: 04ZI0101 | D13: 04-ZT-0101 | E13: 04-FCV-0101 Opening Position Feedback | F13: PL-0408-4"-150A1 | G13: 24E11-P1-PI-1005 | H13: A | I13: AI | J13: 4~20mA | K13: Loop Powered | L13: - | M13: - | R13: 0 | S13: 100 | T13: % | X13: HOLD
A14: =ROW()-3 -> 11 | B14: A | C14: 04ZC0201 | D14: 04-ZC-0201 | E14: 04-FCV-0201 Opening Control | F14: PL-0409-4"-150A1 | G14: 24E11-P1-PI-1005 | H14: A | I14: AO | J14: 4~20mA | K14: Loop Powered | L14: - | M14: - | R14: 0 | S14: 100 | T14: % | X14: HOLD
A15: =ROW()-3 -> 12 | B15: A | C15: 04ZI0201 | D15: 04-ZT-0201 | E15: 04-FCV-0201 Opening Position Feedback | F15: PL-0409-4"-150A1 | G15: 24E11-P1-PI-1005 | H15: A | I15: AI | J15: 4~20mA | K15: Loop Powered | L15: - | M15: - | R15: 0 | S15: 100 | T15: % | X15: HOLD
A16: =ROW()-3 -> 13 | B16: A | C16: 04ZC0301 | D16: 04-ZC-0301 | E16: 04-FCV-0301 Opening Control | F16: PL-0412-4"-150A1 | G16: 24E11-P1-PI-1005 | H16: A | I16: AO | J16: 4~20mA | K16: Loop Powered | L16: - | M16: - | R16: 0 | S16: 100 | T16: % | X16: HOLD
A17: =ROW()-3 -> 14 | B17: A | C17: 04ZI0301 | D17: 04-ZT-0301 | E17: 04-FCV-0301 Opening Position Feedback | F17: PL-0412-4"-150A1 | G17: 24E11-P1-PI-1005 | H17: A | I17: AI | J17: 4~20mA | K17: Loop Powered | L17: - | M17: - | R17: 0 | S17: 100 | T17: % | X17: HOLD
A18: =ROW()-3 -> 15 | B18: A | C18: 04ZC0401 | D18: 04-ZC-0401 | E18: 04-FCV-0401 Opening Control | F18: PL-0413-4"-150A1 | G18: 24E11-P1-PI-1005 | H18: A | I18: AO | J18: 4~20mA | K18: Loop Powered | L18: - | M18: - | R18: 0 | S18: 100 | T18: % | X18: HOLD
A19: =ROW()-3 -> 16 | B19: A | C19: 04ZI0401 | D19: 04-ZT-0401 | E19: 04-FCV-0401 Opening Position Feedback | F19: PL-0413-4"-150A1 | G19: 24E11-P1-PI-1005 | H19: A | I19: AI | J19: 4~20mA | K19: Loop Powered | L19: - | M19: - | R19: 0 | S19: 100 | T19: % | X19: HOLD
A20: =ROW()-3 -> 17 | B20: A | C20: 04ZC0501 | D20: 04-ZC-0501 | E20: 04-FCV-0501 Opening Control | F20: PL-0416-4"-150A1 | G20: 24E11-P1-PI-1006 | H20: A | I20: AO | J20: 4~20mA | K20: Loop Powered | L20: - | M20: - | R20: 0 | S20: 100 | T20: % | X20: HOLD
A21: =ROW()-3 -> 18 | B21: A | C21: 04ZI0501 | D21: 04-ZT-0501 | E21: 04-FCV-0501 Opening Position Feedback | F21: PL-0416-4"-150A1 | G21: 24E11-P1-PI-1006 | H21: A | I21: AI | J21: 4~20mA | K21: Loop Powered | L21: - | M21: - | R21: 0 | S21: 100 | T21: % | X21: HOLD
A22: =ROW()-3 -> 19 | B22: A | C22: 04ZC0601 | D22: 04-ZC-0601 | E22: 04-FCV-0601 Opening Control | F22: PL-0417-4"-150A1 | G22: 24E11-P1-PI-1006 | H22: A | I22: AO | J22: 4~20mA | K22: Loop Powered | L22: - | M22: - | R22: 0 | S22: 100 | T22: % | X22: HOLD
A23: =ROW()-3 -> 20 | B23: A | C23: 04ZI0601 | D23: 04-ZT-0601 | E23: 04-FCV-0601 Opening Position Feedback | F23: PL-0417-4"-150A1 | G23: 24E11-P1-PI-1006 | H23: A | I23: AI | J23: 4~20mA | K23: Loop Powered | L23: - | M23: - | R23: 0 | S23: 100 | T23: % | X23: HOLD
... A27: =ROW()-3 -> 24 | B27: A | C27: 04ZI0801 | D27: 04-ZT-0801 | E27: 04-FCV-0801 Opening Position Feedback | F27: PL-0421-4"-150A1 | G27: 24E11-P1-PI-1006 | H27: A | I27: AI | J27: 4~20mA | K27: Loop Powered | L27: - | M27: - | R27: 0 | S27: 100 | T27: % | X27: HOLD
A28: =ROW()-3 -> 25 | B28: 0 | C28: 04TI0101 | D28: 04-TT-0101 | E28: PLR-402 To Truck Loading Bay 1 Line Temperature | F28: PL-0408-4"-150A1 | G28: 24E11-P1-PI-1005 | H28: A | I28: AI | J28: 4~20mA | K28: Loop Powered | L28: - | M28: - | R28: 0 | S28: 100 | T28: ℃ | X28: HOLD
A29: =ROW()-3 -> 26 | B29: 0 | C29: 04TI0201 | D29: 04-TT-0201 | E29: PLR-402 To Truck Loading Bay 2 Line Temperature | F29: PL-0409-4"-150A1 | G29: 24E11-P1-PI-1005 | H29: A | I29: AI | J29: 4~20mA | K29: Loop Powered | L29: - | M29: - | R29: 0 | S29: 100 | T29: ℃ | X29: HOLD
A30: =ROW()-3 -> 27 | B30: 0 | C30: 04TI0301 | D30: 04-TT-0301 | E30: PLR-403 To Truck Loading Bay 3 Line Temperature | F30: PL-0412-4"-150A1 | G30: 24E11-P1-PI-1005 | H30: A | I30: AI | J30: 4~20mA | K30: Loop Powered | L30: - | M30: - | R30: 0 | S30: 100 | T30: ℃ | X30: HOLD
A31: =ROW()-3 -> 28 | B31: 0 | C31: 04TI0401 | D31: 04-TT-0401 | E31: PLR-403 To Truck Loading Bay 4 Line Temperature | F31: PL-0413-4"-150A1 | G31: 24E11-P1-PI-1005 | H31: A | I31: AI | J31: 4~20mA | K31: Loop Powered | L31: - | M31: - | R31: 0 | S31: 100 | T31: ℃ | X31: HOLD
A32: =ROW()-3 -> 29 | B32: 0 | C32: 04TI0501 | D32: 04-TT-0501 | E32: PLR-404 To Truck Loading Bay 5 Line Temperature | F32: PL-0416-4"-150A1 | G32: 24E11-P1-PI-1006 | H32: A | I32: AI | J32: 4~20mA | K32: Loop Powered | L32: - | M32: - | R32: 0 | S32: 100 | T32: ℃ | X32: HOLD
A33: =ROW()-3 -> 30 | B33: 0 | C33: 04TI0601 | D33: 04-TT-0601 | E33: PLR-404 To Truck Loading Bay 6 Line Temperature | F33: PL-0417-4"-150A1 | G33: 24E11-P1-PI-1006 | H33: A | I33: AI | J33: 4~20mA | K33: Loop Powered | L33: - | M33: - | R33: 0 | S33: 100 | T33: ℃ | X33: HOLD
A34: =ROW()-3 -> 31 | B34: 0 | C34: 04TI0701 | D34: 04-TT-0701 | E34: PLR-405 To Truck Loading Bay 7 Line Temperature | F34: PL-0420-4"-150A1 | G34: 24E11-P1-PI-1006 | H34: A | I34: AI | J34: 4~20mA | K34: Loop Powered | L34: - | M34: - | R34: 0 | S34: 100 | T34: ℃ | X34: HOLD
A35: =ROW()-3 -> 32 | B35: 0 | C35: 04TI0801 | D35: 04-TT-0801 | E35: PLR-405 To Truck Loading Bay 8 Line Temperature | F35: PL-0421-4"-150A1 | G35: 24E11-P1-PI-1006 | H35: A | I35: AI | J35: 4~20mA | K35: Loop Powered | L35: - | M35: - | R35: 0 | S35: 100 | T35: ℃ | X35: HOLD
A36: =ROW()-3 -> 33 | B36: A | C36: 04PI0101 | D36: 04-PT-0101 | E36: PLR-402 To Truck Loading Bay 1 Line Pressure | F36: PL-0408-4"-150A1 | G36: 24E11-P1-PI-1005 | H36: A | I36: AI | J36: 4~20mA | K36: Loop Powered | L36: - | M36: - | R36: 0 | S36: 10 | T36: Barg | X36: HOLD
A37: =ROW()-3 -> 34 | B37: A | C37: 04PI0201 | D37: 04-PT-0201 | E37: PLR-402 To Truck Loading Bay 2 Line Pressure | F37: PL-0409-4"-150A1 | G37: 24E11-P1-PI-1005 | H37: A | I37: AI | J37: 4~20mA | K37: Loop Powered | L37: - | M37: - | R37: 0 | S37: 10 | T37: Barg | X37: HOLD
A38: =ROW()-3 -> 35 | B38: A | C38: 04PI0301 | D38: 04-PT-0301 | E38: PLR-403 To Truck Loading Bay 3 Line Pressure | F38: PL-0412-4"-150A1 | G38: 24E11-P1-PI-1005 | H38: A | I38: AI | J38: 4~20mA | K38: Loop Powered | L38: - | M38: - | R38: 0 | S38: 10 | T38: Barg | X38: HOLD
A39: =ROW()-3 -> 36 | B39: A | C39: 04PI0401 | D39: 04-PT-0401 | E39: PLR-403 To Truck Loading Bay 4 Line Pressure | F39: PL-0413-4"-150A1 | G39: 24E11-P1-PI-1005 | H39: A | I39: AI | J39: 4~20mA | K39: Loop Powered | L39: - | M39: - | R39: 0 | S39: 10 | T39: Barg | X39: HOLD
A40: =ROW()-3 -> 37 | B40: A | C40: 04PI0501 | D40: 04-PT-0501 | E40: PLR-404 To Truck Loading Bay 5 Line Pressure | F40: PL-0416-4"-150A1 | G40: 24E11-P1-PI-1006 | H40: A | I40: AI | J40: 4~20mA | K40: Loop Powered | L40: - | M40: - | R40: 0 | S40: 10 | T40: Barg | X40: HOLD
A41: =ROW()-3 -> 38 | B41: A | C41: 04PI0601 | D41: 04-PT-0601 | E41: PLR-404 To Truck Loading Bay 6 Line Pressure | F41: PL-0417-4"-150A1 | G41: 24E11-P1-PI-1006 | H41: A | I41: AI | J41: 4~20mA | K41: Loop Powered | L41: - | M41: - | R41: 0 | S41: 10 | T41: Barg | X41: HOLD
A42: =ROW()-3 -> 39 | B42: A | C42: 04PI0701 | D42: 04-PT-0701 | E42: PLR-405 To Truck Loading Bay 7 Line Pressure | F42: PL-0420-4"-150A1 | G42: 24E11-P1-PI-1006 | H42: A | I42: AI | J42: 4~20mA | K42: Loop Powered | L42: - | M42: - | R42: 0 | S42: 10 | T42: Barg | X42: HOLD
A43: =ROW()-3 -> 40 | B43: A | C43: 04PI0801 | D43: 04-PT-0801 | E43: PLR-405 To Truck Loading Bay 8 Line Pressure | F43: PL-0421-4"-150A1 | G43: 24E11-P1-PI-1006 | H43: A | I43: AI | J43: 4~20mA | K43: Loop Powered | L43: - | M43: - | R43: 0 | S43: 10 | T43: Barg | X43: HOLD
...

Sheet FIRE F
A1: S/N | B1: Revision No. | C1: DCS Tag Number | D1: Instrument Tag No. | E1: Signal Description | F1: Equipment | G1: P & ID Dwg No. | H1: P&ID Revision No. | I1: IO Type | J1: Signal Type | K1: Power | L1: Zero Stauts | M1: One Stauts | N1: Alarm Setting | R1: Range | T1: Unit | U1: RIO Panel No. | V1: Slot Number | W1: Channel Number | X1: Remarks
N2: LL | O2: L | P2: H | Q2: HH | R2: 0 | S2: 1 | Y2: used | Z2: spare
A3: INSTRUMENT I/O FOR FIRE FIGHTING SYSTEM
A4: =ROW()-3 -> 1 | B4: A | C4: 07FI0001 | D4: 07-FT-0001 | E4: Municipal Water To T-701 Line Flow | F4: FW-0001-4"-150B | G4: 24E11-P1-PI-1010 | H4: A | I4: AI | J4: 4~20mA | K4: Loop Powered | L4: - | M4: -
A5: =ROW()-3 -> 2 | B5: A | C5: 07LI0101 | D5: 07-LT-0101 | E5: T-701 Level | F5: T-701 | G5: 24E11-P1-PI-1010 | H5: A | I5: AI | J5: 4~20mA | K5: Loop Powered | L5: - | M5: -
A6: =ROW()-3 -> 3 | B6: A | C6: 07PI0001 | D6: 07-PT-0001 | E6: Firefighting Water Suppy Bus Pressure | F6: FW-0014-6"-150B | G6: 24E11-P1-PI-1010 | H6: A | I6: AI | J6: 4~20mA | K6: Loop Powered | L6: - | M6: -
A7: =ROW()-3 -> 4 | B7: A | C7: 07LSL0101 | D7: 07-LSL-0101 | E7: P-701 Diesel Oil Tank Low Level Protection | F7: P-701 | G7: 24E11-P1-PI-1010 | H7: A | I7: DI | J7: Dry Contact | K7: - | L7: - | M7: L Level
A8: =ROW()-3 -> 5 | B8: A | C8: 07LSL0201 | D8: 07-LSL-0201 | E8: P-702 Diesel Oil Tank Low Level Protection | F8: P-702 | G8: 24E11-P1-PI-1010 | H8: A | I8: DI | J8: Dry Contact | K8: - | L8: - | M8: L Level

Sheet HOT WATER
A1: S/N | B1: Revision No. | C1: DCS Tag Number | D1: Instrument Tag No. | E1: Signal Description | F1: Equipment | G1: P & ID Dwg No. | H1: P&ID Revision No. | I1: IO Type | J1: Signal Type | K1: Power | L1: Zero Stauts | M1: One Stauts | N1: Alarm Setting | R1: Range | T1: Unit | U1: RIO Panel No. | V1: Slot Number | W1: Channel Number | X1: Remarks
N2: LL | O2: L | P2: H | Q2: HH | R2: 0 | S2: 1 | Y2: used | Z2: spare
A3: INSTRUMENT I/O FOR HOT WATER SYSTEM
A4: =ROW()-3 -> 1 | B4: A | C4: 08LI0101 | D4: 08-LT-0101 | E4: T-801 Level | F4: T-801 | G4: 24E11-P1-PI-1009 | H4: A | I4: AI | J4: 4~20mA | K4: Loop Powered | L4: - | M4: -
A5: =ROW()-3 -> 2 | B5: A | C5: 08TI0001 | D5: 08-TT-0001 | E5: T-801 Discharge Temperature | F5: B-801 | G5: 24E11-P1-PI-1009 | H5: A | I5: AI | J5: 4~20mA | K5: Loop Powered | L5: - | M5: -
A6: =ROW()-3 -> 3 | B6: A | C6: 08TI0002 | D6: 08-TT-0002 | E6: B-801 Discharge Temperature | F6: B-801 | G6: 24E11-P1-PI-1009 | H6: A | I6: AI | J6: 4~20mA | K6: Loop Powered | L6: - | M6: -
A7: =ROW()-3 -> 4 | B7: A | C7: 08TI0003 | D7: 08-TT-0003 | E7: B-801 Suction Temperature | F7: B-801 | G7: 24E11-P1-PI-1009 | H7: A | I7: AI | J7: 4~20mA | K7: Loop Powered | L7: - | M7: -
A8: =ROW()-3 -> 5 | B8: A | D8: 08-LSL-0001 | E8: V-801 Low Level Protection | F8: V-801 | G8: 24E11-P1-PI-1009 | H8: A | I8: DI | J8: Dry Contact | K8: - | L8: - | M8: L Level
A9: =ROW()-3 -> 6 | B9: A | D9: 08-LSH-0001 | E9: V-801 High Level Protection | F9: V-801 | G9: 24E11-P1-PI-1009 | H9: A | I9: DI | J9: Dry Contact | K9: - | L9: - | M9: H Level
A10: =ROW()-3 -> 7 | B10: A | D10: 08-HS-0001A/B | E10: Running Status | F10: P-801 | G10: 24E11-P1-PI-1009 | H10: A | I10: DI | J10: Dry Contact | K10: - | L10: - | M10: Running
A11: =ROW()-3 -> 8 | B11: A | D11: 08-HS-0001A/B | E11: Duty Status | F11: P-801 | G11: 24E11-P1-PI-1009 | H11: A | I11: DI | J11: Dry Contact | K11: - | L11: - | M11: Duty
A12: =ROW()-3 -> 9 | B12: A | D12: 08-HS-0001A/B | E12: Standby Status | F12: P-801 | G12: 24E11-P1-PI-1009 | H12: A | I12: DI | J12: Dry Contact | K12: - | L12: - | M12: Standby
A13: =ROW()-3 -> 10 | B13: A | D13: 08-HS-0001A/B | E13: Trip Status | F13: P-801 | G13: 24E11-P1-PI-1009 | H13: A | I13: DI | J13: Dry Contact | K13: - | L13: - | M13: Trip
A14: =ROW()-3 -> 11 | B14: A | D14: 08-HS-0002A/B | E14: Running Status | F14: P-802 | G14: 24E11-P1-PI-1009 | H14: A | I14: DI | J14: Dry Contact | K14: - | L14: - | M14: Running
A15: =ROW()-3 -> 12 | B15: A | D15: 08-HS-0002A/B | E15: Duty Status | F15: P-802 | G15: 24E11-P1-PI-1009 | H15: A | I15: DI | J15: Dry Contact | K15: - | L15: - | M15: Duty
A16: =ROW()-3 -> 13 | B16: A | D16: 08-HS-0002A/B | E16: Standby Status | F16: P-802 | G16: 24E11-P1-PI-1009 | H16: A | I16: DI | J16: Dry Contact | K16: - | L16: - | M16: Standby
A17: =ROW()-3 -> 14 | B17: A | D17: 08-HS-0002A/B | E17: Trip Status | F17: P-802 | G17: 24E11-P1-PI-1009 | H17: A | I17: DI | J17: Dry Contact | K17: - | L17: - | M17: Trip
A18: =ROW()-3 -> 15 | B18: A | D18: 08-HS-0003A/B | E18: Running Status | F18: P-803 | G18: 24E11-P1-PI-1009 | H18: A | I18: DI | J18: Dry Contact | K18: - | L18: - | M18: Running
A19: =ROW()-3 -> 16 | B19: A | D19: 08-HS-0003A/B | E19: Duty Status | F19: P-803 | G19: 24E11-P1-PI-1009 | H19: A | I19: DI | J19: Dry Contact | K19: - | L19: - | M19: Duty
... A29: =ROW()-3 -> 26 | B29: A | D29: 08-HS-B001 | E29: Trip Status | F29: B-801 | G29: 24E11-P1-PI-1009 | H29: A | I29: DI | J29: Dry Contact | K29: - | L29: - | M29: Trip

Sheet POTABLE WATER
A1: S/N | B1: Revision No. | C1: DCS Tag Number | D1: Instrument Tag No. | E1: Signal Description | F1: Equipment | G1: P & ID Dwg No. | H1: P&ID Revision No. | I1: IO Type | J1: Signal Type | K1: Power | L1: Zero Stauts | M1: One Stauts | N1: Alarm Setting | R1: Range | T1: Unit | U1: RIO Panel No. | V1: Slot Number | W1: Channel Number | X1: Remarks
N2: LL | O2: L | P2: H | Q2: HH | R2: 0 | S2: 1 | Y2: used | Z2: spare
A3: INSTRUMENT I/O FOR POTABLE WATER SYSTEM
A4: =ROW()-3 -> 1 | B4: A | C4: 05FI0001 | D4: 05-FT-0001 | E4: Municipal Water To T-501 Line Flow | F4: T-501 | G4: 24E11-P1-PI-1007 | H4: A | I4: AI | J4: 4~20mA | K4: Loop Powered | L4: - | M4: -
A5: =ROW()-3 -> 2 | B5: A | C5: 05LI0101 | D5: 05-LT-0101 | E5: T-501 Level | F5: T-501 | G5: 24E11-P1-PI-1007 | H5: A | I5: AI | J5: 4~20mA | K5: Loop Powered | L5: - | M5: -
A6: =ROW()-3 -> 3 | B6: A | C6: 05PI0001 | D6: 05-PT-0001 | E6: Potable Water Suppy Bus Pressure | F6: PW-0009-3"-150A3 | G6: 24E11-P1-PI-1007 | H6: A | I6: AI | J6: 4~20mA | K6: Loop Powered | L6: - | M6: - | R6: 0 | S6: 6 | T6: Barg
A7: =ROW()-3 -> 4 | B7: A | C7: 05PA0001 | D7: 05-PS-0001 | E7: Potable Water Suppy Bus H/L Pressure Protection | F7: PW-0009-3"-150A3 | G7: 24E11-P1-PI-1007 | H7: A | I7: DI | J7: Dry Contact | K7: - | L7: - | M7: H/L | O7: 2.5 | P7: 5.5 | T7: Barg
A8: =ROW()-3 -> 5 | B8: A | D8: 05-HS-0001A/B | E8: Running Status | F8: P-501 | G8: 24E11-P1-PI-1004 | H8: A | I8: DI | J8: Dry Contact | K8: - | L8: - | M8: Running
A9: =ROW()-3 -> 6 | B9: A | D9: 05-HS-0001A/B | E9: Duty Status | F9: P-501 | G9: 24E11-P1-PI-1004 | H9: A | I9: DI | J9: Dry Contact | K9: - | L9: - | M9: Duty
A10: =ROW()-3 -> 7 | B10: A | D10: 05-HS-0001A/B | E10: Standby Status | F10: P-501 | G10: 24E11-P1-PI-1004 | H10: A | I10: DI | J10: Dry Contact | K10: - | L10: - | M10: Standby
A11: =ROW()-3 -> 8 | B11: A | D11: 05-HS-0001A/B | E11: Trip Status | F11: P-501 | G11: 24E11-P1-PI-1004 | H11: A | I11: DI | J11: Dry Contact | K11: - | L11: - | M11: Trip
A12: =ROW()-3 -> 9 | B12: A | D12: 05-HS-0002A/B | E12: Running Status | F12: P-502 | G12: 24E11-P1-PI-1004 | H12: A | I12: DI | J12: Dry Contact | K12: - | L12: - | M12: Running
A13: =ROW()-3 -> 10 | B13: A | D13: 05-HS-0002A/B | E13: Duty Status | F13: P-502 | G13: 24E11-P1-PI-1004 | H13: A | I13: DI | J13: Dry Contact | K13: - | L13: - | M13: Duty
A14: =ROW()-3 -> 11 | B14: A | D14: 05-HS-0002A/B | E14: Standby Status | F14: P-502 | G14: 24E11-P1-PI-1004 | H14: A | I14: DI | J14: Dry Contact | K14: - | L14: - | M14: Standby
A15: =ROW()-3 -> 12 | B15: A | D15: 05-HS-0002A/B | E15: Trip Status | F15: P-502 | G15: 24E11-P1-PI-1004 | H15: A | I15: DI | J15: Dry Contact | K15: - | L15: - | M15: Trip

Sheet PLANT AIR
A1: S/N | B1: Revision No. | C1: DCS Tag Number | D1: Instrument Tag No. | E1: Signal Description | F1: Equipment | G1: P & ID Dwg No. | H1: P&ID Revision No. | I1: IO Type | J1: Signal Type | K1: Power | L1: Zero Stauts | M1: One Stauts | N1: Alarm Setting | R1: Range | T1: Unit | U1: RIO Panel No. | V1: Slot Number | W1: Channel Number | X1: Remarks
N2: LL | O2: L | P2: H | Q2: HH | R2: 0 | S2: 1 | Y2: used | Z2: spare
A3: INSTRUMENT I/O FOR PLANT AIR SYETEM
A4: =ROW()-3 -> 1 | B4: A | C4: 06PI0001 | D4: 06-PT-0001 | E4: V-601 Pressure | F4: V-601 | G4: 24E11-P1-PI-1008 | H4: A | I4: AI | J4: 4~20mA | K4: Loop Powered | L4: - | M4: - | R4: 0 | S4: 10 | T4: Barg
A5: =ROW()-3 -> 2 | B5: A | C5: 06PI0002 | D5: 06-PT-0002 | E5: V-602 Pressure | F5: V-602 | G5: 24E11-P1-PI-1008 | H5: A | I5: AI | J5: 4~20mA | K5: Loop Powered | L5: - | M5: - | R5: 0 | S5: 10 | T5: Barg
A6: =ROW()-3 -> 3 | B6: A | C6: 06XA0001 | D6: 06-XA-0001 | E6: C-601 Fault | F6: C-601 | G6: 24E11-P1-PI-1008 | H6: A | I6: DI | J6: Dry Contact | K6: - | L6: - | M6: Fault
A7: =ROW()-3 -> 4 | B7: A | C7: 06ZI0001 | D7: 06-ZI-0001 | E7: C-601 Running/Stop | F7: C-601 | G7: 24E11-P1-PI-1008 | H7: A | I7: DI | J7: Dry Contact | K7: - | L7: Stop | M7: Running
A8: =ROW()-3 -> 5 | B8: A | C8: 06XI001 | D8: 06-XI-0001 | E8: C-601 Loading/unloading | F8: C-601 | G8: 24E11-P1-PI-1008 | H8: A | I8: DI | J8: Dry Contact | K8: - | L8: Loading | M8: Unloading
A9: =ROW()-3 -> 6 | B9: A | C9: 06XA0002 | D9: 06-XA-0002 | E9: C-602 Fault | F9: C-602 | G9: 24E11-P1-PI-1008 | H9: A | I9: DI | J9: Dry Contact | K9: - | L9: - | M9: Fault
A10: =ROW()-3 -> 7 | B10: A | C10: 06ZI0002 | D10: 06-ZI-0002 | E10: C-602 Running/Stop | F10: C-602 | G10: 24E11-P1-PI-1008 | H10: A | I10: DI | J10: Dry Contact | K10: - | L10: Stop | M10: Running
A11: =ROW()-3 -> 8 | B11: A | C11: 06XI002 | D11: 06-XI-0002 | E11: C-602 Loading/unloading | F11: C-602 | G11: 24E11-P1-PI-1008 | H11: A | I11: DI | J11: Dry Contact | K11: - | L11: Loading | M11: Unloading

Sheet TEMPLATE
A1: S/N | B1: Revision No. | C1: DCS Tag Number | D1: Instrument Tag No. | E1: Signal Description | F1: Equipment | G1: P & ID Dwg No. | H1: P&ID Revision No. | I1: IO Type | J1: Signal Type | K1: Zero Stauts | L1: One Stauts | M1: Alarm Setting | Q1: Range | S1: Unit | T1: RIO Panel No. | U1: Slot Number | V1: Channel Number | W1: Remarks
M2: LL | N2: L | O2: H | P2: HH | Q2: 0 | R2: 1 | X2: used | Y2: spare
A3: TRUCK LOADING BAY
A4: 1 | B4: O1 | C4: 41-LAH-0101 | D4: 41-LSH-0101 | E4: 41-TLA-001 Overfilling Protection | F4: 41-TLA-001 | G4: 22E20-C01-P1-PID-4001 | H4: 2 | I4: DI | J4: Dry Contact | L4: H Level
A5: =A4+1 -> 2 | B5: O1 | C5: 41-ZI-0101 | D5: 41-WCV-0101 | E5: 41-WCV-01 Opening Position Feedback | F5: 41-TLA-001 | G5: 22E20-C01-P1-PID-3001 | H5: 2 | I5: AI | J5: 4~20mA | Q5: 0 | R5: 100 | S5: %
A6: =A5+1 -> 3 | B6: O1 | C6: 41-ZC-0101 | D6: 41-WCV-0101 | E6: 41-WCV-01 Opening Control Signal | F6: 41-TLA-001 | G6: 22E20-C01-P1-PID-3001 | H6: 2 | I6: AO | J6: 4~20mA | Q6: 0 | R6: 100 | S6: %
A7: =A6+1 -> 4 | B7: O1 | C7: 41-ZLH-001 | D7: 41-TLA-001 | E7: 41-TLA-001 Truck Loading Arm Parked | F7: 41-TLA-001 | G7: 22E20-C01-P1-PID-4001 | H7: 2 | I7: DI | J7: Dry Contact | L7: Parked
A8: =A7+1 -> 5 | B8: O1 | C8: 41-ZLL-001 | D8: 41-TLA-001 | E8: 41-TLA-001 Truck Loading Arm Extended | F8: 41-TLA-001 | G8: 22E20-C01-P1-PID-4001 | H8: 2 | I8: DI | J8: Dry Contact | L8: Extended
A9: =A8+1 -> 6 | B9: O1 | C9: 41-LAH-0201 | D9: 41-LSH-0201 | E9: 41-TLA-002 Overfilling Protection | F9: 41-TLA-002 | G9: 22E20-C01-P1-PID-4002 | H9: 2 | I9: DI | J9: Dry Contact | L9: H Level
A10: =A9+1 -> 7 | B10: O1 | C10: 41-ZI-0201 | D10: 41-WCV-0201 | E10: 41-WCV-01 Opening Position Feedback | F10: 41-TLA-002 | G10: 22E20-C01-P1-PID-3002 | H10: 2 | I10: AI | J10: 4~20mA | Q10: 0 | R10: 100 | S10: %
A11: =A10+1 -> 8 | B11: O1 | C11: 41-ZC-0201 | D11: 41-WCV-0201 | E11: 41-WCV-01 Opening Control Signal | F11: 41-TLA-002 | G11: 22E20-C01-P1-PID-3002 | H11: 2 | I11: AO | J11: 4~20mA | Q11: 0 | R11: 100 | S11: %
A12: =A11+1 -> 9 | B12: O1 | C12: 41-ZLH-002 | D12: 41-TLA-002 | E12: 41-TLA-002 Truck Loading Arm Parked | F12: 41-TLA-002 | G12: 22E20-C01-P1-PID-4001 | H12: 2 | I12: DI | J12: Dry Contact | L12: Parked
A13: =A12+1 -> 10 | B13: O1 | C13: 41-ZLL-002 | D13: 41-TLA-002 | E13: 41-TLA-002 Truck Loading Arm Extended | F13: 41-TLA-002 | G13: 22E20-C01-P1-PID-4001 | H13: 2 | I13: DI | J13: Dry Contact | L13: Extended
A14: =A13+1 -> 11 | B14: O1 | C14: 41-ED-0001 | D14: 41-ED-0001 | E14: 41-TLB-001 Grouding Unit | F14: 41-TLB-001 | G14: 22E20-C01-P1-PID-4001 | H14: 2 | I14: DI | J14: Dry Contact | K14: Normal | L14: Grounding Fault
A15: =A14+1 -> 12 | B15: O1 | C15: 41-AVA-0001 | D15: 41-AVA-0001 | E15: 41-TLB-001 Audible & Visual Alarm | F15: 41-TLB-001 | G15: 22E20-C01-P1-PID-4001 | H15: 2 | I15: DO | J15: Dry Contact | L15: Alarm
A17: =A15+1 -> 13 | B17: O1 | C17: 42-LAH-0101 | D17: 42-LSH-0101 | E17: 42-TLA-001 Overfilling Protection | F17: 42-TLA-001 | G17: 22E20-C01-P1-PID-4001 | H17: 2 | I17: DI | J17: Dry Contact | L17: H Level
A18: =A17+1 -> 14 | B18: O1 | C18: 42-ZI-0101 | D18: 42-WCV-0101 | E18: 42-WCV-01 Opening Position Feedback | F18: 42-TLA-001 | G18: 22E20-C01-P1-PID-3001 | H18: 2 | I18: AI | J18: 4~20mA | Q18: 0 | R18: 100 | S18: %
A19: =A18+1 -> 15 | B19: O1 | C19: 42-ZC-0101 | D19: 42-WCV-0101 | E19: 42-WCV-01 Opening Control Signal | F19: 42-TLA-001 | G19: 22E20-C01-P1-PID-3001 | H19: 2 | I19: AO | J19: 4~20mA | Q19: 0 | R19: 100 | S19: %
A20: =A19+1 -> 16 | B20: O1 | C20: 42-ZLH-001 | D20: 42-TLA-001 | E20: 42-TLA-001 Truck Loading Arm Parked | F20: 42-TLA-001 | G20: 22E20-C01-P1-PID-4001 | H20: 2 | I20: DI | J20: Dry Contact | L20: Parked
A21: =A20+1 -> 17 | B21: O1 | C21: 42-ZLL-001 | D21: 42-TLA-001 | E21: 42-TLA-001 Truck Loading Arm Extended | F21: 42-TLA-001 | G21: 22E20-C01-P1-PID-4001 | H21: 2 | I21: DI | J21: Dry Contact | L21: Extended
A22: =A21+1 -> 18 | B22: O1 | C22: 42-LAH-0201 | D22: 42-LSH-0201 | E22: 42-TLA-002 Overfilling Protection | F22: 42-TLA-002 | G22: 22E20-C01-P1-PID-4002 | H22: 2 | I22: DI | J22: Dry Contact | L22: H Level
A23: =A22+1 -> 19 | B23: O1 | C23: 42-ZI-0201 | D23: 42-WCV-0201 | E23: 42-WCV-01 Opening Position Feedback | F23: 42-TLA-002 | G23: 22E20-C01-P1-PID-3002 | H23: 2 | I23: AI | J23: 4~20mA | Q23: 0 | R23: 100 | S23: %
A24: =A23+1 -> 20 | B24: O1 | C24: 42-ZC-0201 | D24: 42-WCV-0201 | E24: 42-WCV-01 Opening Control Signal | F24: 42-TLA-002 | G24: 22E20-C01-P1-PID-3002 | H24: 2 | I24: AO | J24: 4~20mA | Q24: 0 | R24: 100 | S24: %
A25: =A24+1 -> 21 | B25: O1 | C25: 42-ZLH-002 | D25: 42-TLA-002 | E25: 42-TLA-002 Truck Loading Arm Parked | F25: 42-TLA-002 | G25: 22E20-C01-P1-PID-4001 | H25: 2 | I25: DI | J25: Dry Contact | L25: Parked
A26: =A25+1 -> 22 | B26: O1 | C26: 42-ZLL-002 | D26: 42-TLA-002 | E26: 42-TLA-002 Truck Loading Arm Extended | F26: 42-TLA-002 | G26: 22E20-C01-P1-PID-4001 | H26: 2 | I26: DI | J26: Dry Contact | L26: Extended
A27: =A26+1 -> 23 | B27: O1 | C27: 42-ED-0001 | D27: 42-ED-0001 | E27: 42-TLB-001 Grouding Unit | F27: 42-TLB-001 | G27: 22E20-C01-P1-PID-4001 | H27: 2 | I27: DI | J27: Dry Contact | K27: Normal | L27: Grounding Fault
A28: =A27+1 -> 24 | B28: O1 | C28: 42-AVA-0001 | D28: 42-AVA-0001 | E28: 42-TLB-001 Audible & Visual Alarm | F28: 42-TLB-001 | G28: 22E20-C01-P1-PID-4001 | H28: 2 | I28: DO | J28: Dry Contact | L28: Alarm
A30: =A28+1 -> 25 | B30: O1 | C30: 43-LAH-0101 | D30: 43-LSH-0101 | E30: 43-TLA-001 Overfilling Protection | F30: 43-TLA-001 | G30: 22E20-C01-P1-PID-4001 | H30: 2 | I30: DI | J30: Dry Contact | L30: H Level
A31: =A30+1 -> 26 | B31: O1 | C31: 43-ZI-0101 | D31: 43-WCV-0101 | E31: 43-WCV-01 Opening Position Feedback | F31: 43-TLA-001 | G31: 22E20-C01-P1-PID-3001 | H31: 2 | I31: AI | J31: 4~20mA | Q31: 0 | R31: 100 | S31: %
A32: =A31+1 -> 27 | B32: O1 | C32: 43-ZC-0101 | D32: 43-WCV-0101 | E32: 43-WCV-01 Opening Control Signal | F32: 43-TLA-001 | G32: 22E20-C01-P1-PID-3001 | H32: 2 | I32: AO | J32: 4~20mA | Q32: 0 | R32: 100 | S32: %
A33: =A32+1 -> 28 | B33: O1 | C33: 43-ZLH-001 | D33: 43-TLA-001 | E33: 43-TLA-001 Truck Loading Arm Parked | F33: 43-TLA-001 | G33: 22E20-C01-P1-PID-4001 | H33: 2 | I33: DI | J33: Dry Contact | L33: Parked
A34: =A33+1 -> 29 | B34: O1 | C34: 43-ZLL-001 | D34: 43-TLA-001 | E34: 43-TLA-001 Truck Loading Arm Extended | F34: 43-TLA-001 | G34: 22E20-C01-P1-PID-4001 | H34: 2 | I34: DI | J34: Dry Contact | L34: Extended
A35: =A34+1 -> 30 | B35: O1 | C35: 43-LAH-0201 | D35: 43-LSH-0201 | E35: 43-TLA-002 Overfilling Protection | F35: 43-TLA-002 | G35: 22E20-C01-P1-PID-4002 | H35: 2 | I35: DI | J35: Dry Contact | L35: H Level
A36: =A35+1 -> 31 | B36: O1 | C36: 43-ZI-0201 | D36: 43-WCV-0201 | E36: 43-WCV-01 Opening Position Feedback | F36: 43-TLA-002 | G36: 22E20-C01-P1-PID-3002 | H36: 2 | I36: AI | J36: 4~20mA | Q36: 0 | R36: 100 | S36: %
A37: =A36+1 -> 32 | B37: O1 | C37: 43-ZC-0201 | D37: 43-WCV-0201 | E37: 43-WCV-01 Opening Control Signal | F37: 43-TLA-002 | G37: 22E20-C01-P1-PID-3002 | H37: 2 | I37: AO | J37: 4~20mA | Q37: 0 | R37: 100 | S37: %
A38: =A37+1 -> 33 | B38: O1 | C38: 43-ZLH-002 | D38: 43-TLA-002 | E38: 43-TLA-002 Truck Loading Arm Parked | F38: 43-TLA-002 | G38: 22E20-C01-P1-PID-4001 | H38: 2 | I38: DI | J38: Dry Contact | L38: Parked
A39: =A38+1 -> 34 | B39: O1 | C39: 43-ZLL-002 | D39: 43-TLA-002 | E39: 43-TLA-002 Truck Loading Arm Extended | F39: 43-TLA-002 | G39: 22E20-C01-P1-PID-4001 | H39: 2 | I39: DI | J39: Dry Contact | L39: Extended
A40: =A39+1 -> 35 | B40: O1 | C40: 43-ED-0001 | D40: 43-ED-0001 | E40: 43-TLB-001 Grouding Unit | F40: 43-TLB-001 | G40: 22E20-C01-P1-PID-4001 | H40: 2 | I40: DI | J40: Dry Contact | K40: Normal | L40: Grounding Fault
A41: =A40+1 -> 36 | B41: O1 | C41: 43-AVA-0001 | D41: 43-AVA-0001 | E41: 43-TLB-001 Audible & Visual Alarm | F41: 43-TLB-001 | G41: 22E20-C01-P1-PID-4001 | H41: 2 | I41: DO | J41: Dry Contact | L41: Alarm
A43: =A41+1 -> 37 | B43: O1 | C43: 44-LAH-0101 | D43: 44-LSH-0101 | E43: 44-TLA-001 Overfilling Protection | F43: 44-TLA-001 | G43: 22E20-C01-P1-PID-4001 | H43: 2 | I43: DI | J43: Dry Contact | L43: H Level
...
